<!--
    ==================================
    This file was autogenerated from solo12.xml by generate_model.py on 21/02/25 10:25.
    The original .xml included 12 <include_with_attrs> elements.
    ==================================
    --><mujoco model="solo12">
  <compiler angle="radian" meshdir="meshes/" fusestatic="false"/>

  <default>
    <default class="visual">
      <geom group="2" type="mesh" contype="0" conaffinity="0"/>
    </default>
    <default class="collision">
      <geom group="3" type="mesh"/>
    </default>
    <default class="affine">
      <position kp="15" ctrlrange="-3.14 3.14" forcerange="-10 10"/>
    </default>
    <joint type="hinge" damping="1" frictionloss="0.1"/>

    <default class="solo12foot">
      <site group="1" pos="0.0 0 0.0" />
      <geom rgba="0.231373 0.380392 0.705882 1" />
    </default>

    <default class="foot">
      <geom type="sphere" size="0.001" pos="-0.0 0 0.00" solimp="0.00015 1 0.031"
          friction="1.0 0.3 0.3" condim="3" />
    </default>
  </default>
  
  <!-- Collision / visual meshes used during the simulation -->
  <asset>
    <include file="meshes.xml"/>
    <include file="materials.xml"/>	
    <texture type="skybox" builtin="gradient" rgb1="1.0 1.0 1.0" rgb2="1.0 1.0 1.0" width="512" height="512"/>
    <texture name="plane" type="2d" builtin="flat" rgb1="0.188 0.188 0.188" rgb2="0.188 0.188 0.188" width="512" height="512" mark="cross" markrgb="1 1 1"/>
    <material name="plane" reflectance="0.0" texture="plane" texrepeat="3 3" texuniform="true"/>
    <material name="black" rgba="0 0 0 1" />
  </asset>

  <worldbody>
    <light directional="true" diffuse=".8 .8 .8" pos="0 0 10" dir="0 0 -10"/>
    <geom name='floor' type='plane' conaffinity='1' condim='3' contype='1' rgba="0.5 0.9 0.9 0.1" material='plane' pos='0 0 0' size='0 0 1'/>
    <!-- Robot base -->
    <body name="base_link" pos="0 0 0.4">
      <!-- <joint type="free"/> -->
      <inertial pos="-0.00082966 1.05e-06 -0.0006021" quat="-0.00116678 0.706653 0.00115432 0.707559" mass="1.25124" diaginertia="0.0160537 0.0138852 0.00266206"/>
      <joint type="free" />
      <include file="meshes/solo_12_base/solo_12_base.xml"/>

      <!-- Front left shoulder  -->
      <body name="FL_SHOULDER" pos="0.2141 0.0875 0">
        <inertial pos="-0.0940725 -0.00438935 1.384e-05" quat="0.525393 0.524526 0.474075 0.473379" mass="0.14196" diaginertia="0.000386433 0.0003805 2.42272e-05"/>
        <joint name="FL_HAA" pos="0 0 0" axis="1 0 0" range="-10 10"/>
        <!-- Front left upper leg -->
        <body name="FL_UPPER_LEG" pos="-0.0195 0.014 0">
          <inertial pos="1.53e-05 0.0176764 -0.0783823" quat="0.705254 -0.0412383 0.0411345 0.706558" mass="0.147373" diaginertia="0.000421743 0.0004154 2.44467e-05"/>
          <joint name="FL_HFE" pos="0 0 0" axis="0 1 0" range="-10 10"/>
          <!-- Front left lower leg -->
          <body name="FL_LOWER_LEG" pos="0 0.03745 -0.16">
            <inertial pos="0 0.00776716 -0.0700388" quat="0.707057 -0.00837059 0.00837059 0.707057" mass="0.0231829" diaginertia="8.58474e-05 8.508e-05 1.34264e-06"/>
            <joint name="FL_KFE" pos="0 0 0" axis="0 1 0" range="-10 10"/>
            <!-- Front left foot pose -->
            <geom name="FL" class="foot" />
            <site name="FL_foot" class="solo12foot" />

            <!-- <geom mesh="solo_lower_leg_v2_0" material="metal_grey" class="visual"/>
            <geom mesh="solo_lower_leg_v2_1" material="pla_orange" class="visual"/>
            <geom mesh="solo_lower_leg_v2_2" material="pla_grey" class="visual"/> -->
            <!-- <geom mesh="solo_lower_leg_v2_collision_0" class="collision"/>
            <geom mesh="solo_lower_leg_v2_collision_1" class="collision"/>
            <geom mesh="solo_lower_leg_v2_collision_2" class="collision"/>
            <geom mesh="solo_lower_leg_v2_collision_3" class="collision"/>
            <geom mesh="solo_lower_leg_v2_collision_4" class="collision"/>
            <geom mesh="solo_lower_leg_v2_collision_5" class="collision"/> -->
          </body>
          <!-- <geom mesh="solo_upper_leg_4" material="metal_silver" class="visual"/>
          <geom mesh="solo_upper_leg_5" material="metal_grey" class="visual"/>
          <geom mesh="solo_upper_leg_6" material="metal_gold" class="visual"/>
          <geom mesh="solo_upper_leg_7" material="metal_dark" class="visual"/>
          <geom mesh="solo_upper_leg_12" material="metal_dark" class="visual"/>
          <geom mesh="solo_upper_leg_16" material="metal_grey" class="visual"/>
          <geom mesh="solo_upper_leg_17" material="pla_grey" class="visual"/>
          <geom mesh="solo_upper_leg_18" material="pla_white" class="visual"/>
          <geom mesh="solo_upper_leg_19" material="metal_grey" class="visual"/> -->
          <!-- <geom mesh="solo_upper_leg_collision_0" class="collision"/>
          <geom mesh="solo_upper_leg_collision_1" class="collision"/>
          <geom mesh="solo_upper_leg_collision_2" class="collision"/>
          <geom mesh="solo_upper_leg_collision_3" class="collision"/>
          <geom mesh="solo_upper_leg_collision_4" class="collision"/>
          <geom mesh="solo_upper_leg_collision_5" class="collision"/> -->
        </body>
        <!-- <geom mesh="solo12_hip_fe_0" material="metal_grey" class="visual"/>
        <geom mesh="solo12_hip_fe_1" material="pla_grey" class="visual"/>
        <geom mesh="solo12_hip_fe_3" material="metal_grey" class="visual"/>
        <geom mesh="solo12_hip_fe_7" material="pla_white" class="visual"/>
        <geom mesh="solo12_hip_fe_8" material="metal_silver" class="visual"/>
        <geom mesh="solo12_hip_fe_10" material="metal_dark" class="visual"/>
        <geom mesh="solo12_hip_fe_11" material="metal_gold" class="visual"/>
        <geom mesh="solo12_hip_fe_12" material="metal_dark" class="visual"/>
        <geom mesh="solo12_hip_fe_13" material="metal_dark" class="visual"/>
        <geom mesh="solo12_hip_fe_14" material="metal_dark" class="visual"/> -->
        <!-- <geom mesh="solo12_hip_fe_collision_0" class="collision"/>
        <geom mesh="solo12_hip_fe_collision_1" class="collision"/>
        <geom mesh="solo12_hip_fe_collision_2" class="collision"/>
        <geom mesh="solo12_hip_fe_collision_3" class="collision"/>
        <geom mesh="solo12_hip_fe_collision_4" class="collision"/>
        <geom mesh="solo12_hip_fe_collision_5" class="collision"/> -->
      </body>

      <!-- Front right shoulder  -->
      <body name="FR_SHOULDER" pos="0.2141 -0.0875 0">
        <inertial pos="-0.0940725 0.00438935 -1.384e-05" quat="0.474075 0.473379 0.525393 0.524526" mass="0.14196" diaginertia="0.000386433 0.0003805 2.42272e-05"/>
        <joint name="FR_HAA" pos="0 0 0" axis="1 0 0" range="-10 10"/>
        
        <geom material="pla_grey" mesh="hip_adapter" pos="-0.1875 0.0 0.0" class="visual"/>

        <!-- Front right upper leg -->
        <body name="FR_UPPER_LEG" pos="-0.0195 -0.014 0">
          <inertial pos="-1.53e-05 -0.0176764 -0.0783823" quat="0.705254 0.0412383 -0.0411345 0.706558" mass="0.147373" diaginertia="0.000421743 0.0004154 2.44467e-05"/>
          <joint name="FR_HFE" pos="0 0 0" axis="0 1 0" range="-10 10"/>
          <!-- Front right lower leg -->
          <body name="FR_LOWER_LEG" pos="0 -0.03745 -0.16">
            <inertial pos="0 -0.00776716 -0.0700388" quat="0.707057 0.00837059 -0.00837059 0.707057" mass="0.0231829" diaginertia="8.58474e-05 8.508e-05 1.34264e-06"/>
            <joint name="FR_KFE" pos="0 0 0" axis="0 1 0" range="-10 10"/>
            <!-- Front right foot pose -->
            <geom name="FR" class="foot" />
            <site name="FR_foot" class="solo12foot" />

            <!-- <geom mesh="solo_lower_leg_v2_0" material="metal_grey" class="visual" euler="0.0 0.0 3.1415"/>
            <geom mesh="solo_lower_leg_v2_1" material="pla_orange" class="visual" euler="0.0 0.0 3.1415"/>
            <geom mesh="solo_lower_leg_v2_2" material="pla_grey" class="visual" euler="0.0 0.0 3.1415"/> -->
            <!-- <geom mesh="solo_lower_leg_v2_collision_0" class="collision" euler="0.0 0.0 3.1415"/>
            <geom mesh="solo_lower_leg_v2_collision_1" class="collision" euler="0.0 0.0 3.1415"/>
            <geom mesh="solo_lower_leg_v2_collision_2" class="collision" euler="0.0 0.0 3.1415"/>
            <geom mesh="solo_lower_leg_v2_collision_3" class="collision" euler="0.0 0.0 3.1415"/>
            <geom mesh="solo_lower_leg_v2_collision_4" class="collision" euler="0.0 0.0 3.1415"/>
            <geom mesh="solo_lower_leg_v2_collision_5" class="collision" euler="0.0 0.0 3.1415"/> -->
          </body>
          <!-- <geom mesh="solo_upper_leg_4" material="metal_silver" class="visual" euler="0.0 0.0 3.1415"/>
          <geom mesh="solo_upper_leg_5" material="metal_grey" class="visual" euler="0.0 0.0 3.1415"/>
          <geom mesh="solo_upper_leg_6" material="metal_gold" class="visual" euler="0.0 0.0 3.1415"/>
          <geom mesh="solo_upper_leg_7" material="metal_dark" class="visual" euler="0.0 0.0 3.1415"/>
          <geom mesh="solo_upper_leg_12" material="metal_dark" class="visual" euler="0.0 0.0 3.1415"/>
          <geom mesh="solo_upper_leg_16" material="metal_grey" class="visual" euler="0.0 0.0 3.1415"/>
          <geom mesh="solo_upper_leg_17" material="pla_grey" class="visual" euler="0.0 0.0 3.1415"/>
          <geom mesh="solo_upper_leg_18" material="pla_white" class="visual" euler="0.0 0.0 3.1415"/>
          <geom mesh="solo_upper_leg_19" material="metal_grey" class="visual" euler="0.0 0.0 3.1415"/> -->
          <!-- <geom mesh="solo_upper_leg_collision_0" class="collision" euler="0.0 0.0 3.1415"/>
          <geom mesh="solo_upper_leg_collision_1" class="collision" euler="0.0 0.0 3.1415"/>
          <geom mesh="solo_upper_leg_collision_2" class="collision" euler="0.0 0.0 3.1415"/>
          <geom mesh="solo_upper_leg_collision_3" class="collision" euler="0.0 0.0 3.1415"/>
          <geom mesh="solo_upper_leg_collision_4" class="collision" euler="0.0 0.0 3.1415"/>
          <geom mesh="solo_upper_leg_collision_5" class="collision" euler="0.0 0.0 3.1415"/> -->
        </body>
        <!-- <geom mesh="solo12_hip_fe_0" material="metal_grey" class="visual" euler="-3.1415 0.0 0.0"/>
        <geom mesh="solo12_hip_fe_1" material="pla_grey" class="visual" euler="-3.1415 0.0 0.0"/>
        <geom mesh="solo12_hip_fe_3" material="metal_grey" class="visual" euler="-3.1415 0.0 0.0"/>
        <geom mesh="solo12_hip_fe_7" material="pla_white" class="visual" euler="-3.1415 0.0 0.0"/>
        <geom mesh="solo12_hip_fe_8" material="metal_silver" class="visual" euler="-3.1415 0.0 0.0"/>
        <geom mesh="solo12_hip_fe_10" material="metal_dark" class="visual" euler="-3.1415 0.0 0.0"/>
        <geom mesh="solo12_hip_fe_11" material="metal_gold" class="visual" euler="-3.1415 0.0 0.0"/>
        <geom mesh="solo12_hip_fe_12" material="metal_dark" class="visual" euler="-3.1415 0.0 0.0"/>
        <geom mesh="solo12_hip_fe_13" material="metal_dark" class="visual" euler="-3.1415 0.0 0.0"/>
        <geom mesh="solo12_hip_fe_14" material="metal_dark" class="visual" euler="-3.1415 0.0 0.0"/> -->
        <!-- <geom mesh="solo12_hip_fe_collision_0" class="collision" euler="-3.1415 0.0 0.0"/>
        <geom mesh="solo12_hip_fe_collision_1" class="collision" euler="-3.1415 0.0 0.0"/>
        <geom mesh="solo12_hip_fe_collision_2" class="collision" euler="-3.1415 0.0 0.0"/>
        <geom mesh="solo12_hip_fe_collision_3" class="collision" euler="-3.1415 0.0 0.0"/>
        <geom mesh="solo12_hip_fe_collision_4" class="collision" euler="-3.1415 0.0 0.0"/>
        <geom mesh="solo12_hip_fe_collision_5" class="collision" euler="-3.1415 0.0 0.0"/> -->
      </body>

      <!-- Hind left shoulder  -->
      <body name="HL_SHOULDER" pos="-0.2141 0.0875 0">
        <inertial pos="0.0940725 -0.00438935 -1.384e-05" quat="0.473379 0.474075 0.524526 0.525393" mass="0.14196" diaginertia="0.000386433 0.0003805 2.42272e-05"/>
        <joint name="HL_HAA" pos="0 0 0" axis="1 0 0" range="-10 10"/>

        <geom material="pla_grey" mesh="hip_adapter" pos="0.1875 0.0 0.0" euler="0.0 0.0 3.1415" class="visual"/>

        <!-- Hind left upper leg  -->
        <body name="HL_UPPER_LEG" pos="0.0195 0.014 0">
          <inertial pos="1.53e-05 0.0176764 -0.0783823" quat="0.705254 -0.0412383 0.0411345 0.706558" mass="0.147373" diaginertia="0.000421743 0.0004154 2.44467e-05"/>
          <joint name="HL_HFE" pos="0 0 0" axis="0 1 0" range="-10 10"/>
          <!-- Hind left lower leg  -->
          <body name="HL_LOWER_LEG" pos="0 0.03745 -0.16">
            <inertial pos="0 0.00776716 -0.0700388" quat="0.707057 -0.00837059 0.00837059 0.707057" mass="0.0231829" diaginertia="8.58474e-05 8.508e-05 1.34264e-06"/>
            <joint name="HL_KFE" pos="0 0 0" axis="0 1 0" range="-10 10"/>
            <!-- Hind left foot pose  -->
            <geom name="HL" class="foot" />
            <site name="HL_foot" class="solo12foot" />

            <!-- <geom mesh="solo_lower_leg_v2_0" material="metal_grey" class="visual"/>
            <geom mesh="solo_lower_leg_v2_1" material="pla_orange" class="visual"/>
            <geom mesh="solo_lower_leg_v2_2" material="pla_grey" class="visual"/> -->
            <!-- <geom mesh="solo_lower_leg_v2_collision_0" class="collision"/>
            <geom mesh="solo_lower_leg_v2_collision_1" class="collision"/>
            <geom mesh="solo_lower_leg_v2_collision_2" class="collision"/>
            <geom mesh="solo_lower_leg_v2_collision_3" class="collision"/>
            <geom mesh="solo_lower_leg_v2_collision_4" class="collision"/>
            <geom mesh="solo_lower_leg_v2_collision_5" class="collision"/> -->
          </body>
          <!-- <geom mesh="solo_upper_leg_4" material="metal_silver" class="visual"/>
          <geom mesh="solo_upper_leg_5" material="metal_grey" class="visual"/>
          <geom mesh="solo_upper_leg_6" material="metal_gold" class="visual"/>
          <geom mesh="solo_upper_leg_7" material="metal_dark" class="visual"/>
          <geom mesh="solo_upper_leg_12" material="metal_dark" class="visual"/>
          <geom mesh="solo_upper_leg_16" material="metal_grey" class="visual"/>
          <geom mesh="solo_upper_leg_17" material="pla_grey" class="visual"/>
          <geom mesh="solo_upper_leg_18" material="pla_white" class="visual"/>
          <geom mesh="solo_upper_leg_19" material="metal_grey" class="visual"/> -->
          <!-- <geom mesh="solo_upper_leg_collision_0" class="collision"/>
          <geom mesh="solo_upper_leg_collision_1" class="collision"/>
          <geom mesh="solo_upper_leg_collision_2" class="collision"/>
          <geom mesh="solo_upper_leg_collision_3" class="collision"/>
          <geom mesh="solo_upper_leg_collision_4" class="collision"/>
          <geom mesh="solo_upper_leg_collision_5" class="collision"/> -->
        </body>
        <!-- <geom mesh="solo12_hip_fe_0" material="metal_grey" class="visual" euler="0.0 -3.1415 0.0"/>
        <geom mesh="solo12_hip_fe_1" material="pla_grey" class="visual" euler="0.0 -3.1415 0.0"/>
        <geom mesh="solo12_hip_fe_3" material="metal_grey" class="visual" euler="0.0 -3.1415 0.0"/>
        <geom mesh="solo12_hip_fe_7" material="pla_white" class="visual" euler="0.0 -3.1415 0.0"/>
        <geom mesh="solo12_hip_fe_8" material="metal_silver" class="visual" euler="0.0 -3.1415 0.0"/>
        <geom mesh="solo12_hip_fe_10" material="metal_dark" class="visual" euler="0.0 -3.1415 0.0"/>
        <geom mesh="solo12_hip_fe_11" material="metal_gold" class="visual" euler="0.0 -3.1415 0.0"/>
        <geom mesh="solo12_hip_fe_12" material="metal_dark" class="visual" euler="0.0 -3.1415 0.0"/>
        <geom mesh="solo12_hip_fe_13" material="metal_dark" class="visual" euler="0.0 -3.1415 0.0"/>
        <geom mesh="solo12_hip_fe_14" material="metal_dark" class="visual" euler="0.0 -3.1415 0.0"/> -->
        <!-- <geom mesh="solo12_hip_fe_collision_0" class="collision" euler="0.0 -3.1415 0.0"/>
        <geom mesh="solo12_hip_fe_collision_1" class="collision" euler="0.0 -3.1415 0.0"/>
        <geom mesh="solo12_hip_fe_collision_2" class="collision" euler="0.0 -3.1415 0.0"/>
        <geom mesh="solo12_hip_fe_collision_3" class="collision" euler="0.0 -3.1415 0.0"/>
        <geom mesh="solo12_hip_fe_collision_4" class="collision" euler="0.0 -3.1415 0.0"/>
        <geom mesh="solo12_hip_fe_collision_5" class="collision" euler="0.0 -3.1415 0.0"/> -->
      </body>

      <!-- Hind right shoulder  -->
      <body name="HR_SHOULDER" pos="-0.2141 -0.0875 0">
        <inertial pos="0.0940725 0.00438935 1.384e-05" quat="0.524526 0.525393 0.473379 0.474075" mass="0.14196" diaginertia="0.000386433 0.0003805 2.42272e-05"/>
        <joint name="HR_HAA" pos="0 0 0" axis="1 0 0" range="-10 10"/>
        <!-- Hind right upper leg  -->
        <body name="HR_UPPER_LEG" pos="0.0195 -0.014 0">
          <inertial pos="-1.53e-05 -0.0176764 -0.0783823" quat="0.705254 0.0412383 -0.0411345 0.706558" mass="0.147373" diaginertia="0.000421743 0.0004154 2.44467e-05"/>
          <joint name="HR_HFE" pos="0 0 0" axis="0 1 0" range="-10 10"/>
          <!-- Hind right lower leg  -->
          <body name="HR_LOWER_LEG" pos="0 -0.03745 -0.16">
            <inertial pos="0 -0.00776716 -0.0700388" quat="0.707057 0.00837059 -0.00837059 0.707057" mass="0.0231829" diaginertia="8.58474e-05 8.508e-05 1.34264e-06"/>
            <joint name="HR_KFE" pos="0 0 0" axis="0 1 0" range="-10 10"/>
            <!-- Hind right foot pose  -->
            <geom name="HR" class="foot" />
            <site name="HR_foot" class="solo12foot" />

            <!-- <geom mesh="solo_lower_leg_v2_0" material="metal_grey" class="visual" euler="0.0 0.0 3.1415"/>
            <geom mesh="solo_lower_leg_v2_1" material="pla_orange" class="visual" euler="0.0 0.0 3.1415"/>
            <geom mesh="solo_lower_leg_v2_2" material="pla_grey" class="visual" euler="0.0 0.0 3.1415"/> -->
            <!-- <geom mesh="solo_lower_leg_v2_collision_0" class="collision" euler="0.0 0.0 3.1415"/>
            <geom mesh="solo_lower_leg_v2_collision_1" class="collision" euler="0.0 0.0 3.1415"/>
            <geom mesh="solo_lower_leg_v2_collision_2" class="collision" euler="0.0 0.0 3.1415"/>
            <geom mesh="solo_lower_leg_v2_collision_3" class="collision" euler="0.0 0.0 3.1415"/>
            <geom mesh="solo_lower_leg_v2_collision_4" class="collision" euler="0.0 0.0 3.1415"/>
            <geom mesh="solo_lower_leg_v2_collision_5" class="collision" euler="0.0 0.0 3.1415"/> -->
          </body>
          <!-- <geom mesh="solo_upper_leg_4" material="metal_silver" class="visual" euler="0.0 0.0 3.1415"/>
          <geom mesh="solo_upper_leg_5" material="metal_grey" class="visual" euler="0.0 0.0 3.1415"/>
          <geom mesh="solo_upper_leg_6" material="metal_gold" class="visual" euler="0.0 0.0 3.1415"/>
          <geom mesh="solo_upper_leg_7" material="metal_dark" class="visual" euler="0.0 0.0 3.1415"/>
          <geom mesh="solo_upper_leg_12" material="metal_dark" class="visual" euler="0.0 0.0 3.1415"/>
          <geom mesh="solo_upper_leg_16" material="metal_grey" class="visual" euler="0.0 0.0 3.1415"/>
          <geom mesh="solo_upper_leg_17" material="pla_grey" class="visual" euler="0.0 0.0 3.1415"/>
          <geom mesh="solo_upper_leg_18" material="pla_white" class="visual" euler="0.0 0.0 3.1415"/>
          <geom mesh="solo_upper_leg_19" material="metal_grey" class="visual" euler="0.0 0.0 3.1415"/> -->
          <!-- <geom mesh="solo_upper_leg_collision_0" class="collision" euler="0.0 0.0 3.1415"/>
          <geom mesh="solo_upper_leg_collision_1" class="collision" euler="0.0 0.0 3.1415"/>
          <geom mesh="solo_upper_leg_collision_2" class="collision" euler="0.0 0.0 3.1415"/>
          <geom mesh="solo_upper_leg_collision_3" class="collision" euler="0.0 0.0 3.1415"/>
          <geom mesh="solo_upper_leg_collision_4" class="collision" euler="0.0 0.0 3.1415"/>
          <geom mesh="solo_upper_leg_collision_5" class="collision" euler="0.0 0.0 3.1415"/> -->
        </body>
        <!-- <geom mesh="solo12_hip_fe_0" material="metal_grey" class="visual" euler="0.0 0.0 3.1415"/>
        <geom mesh="solo12_hip_fe_1" material="pla_grey" class="visual" euler="0.0 0.0 3.1415"/>
        <geom mesh="solo12_hip_fe_3" material="metal_grey" class="visual" euler="0.0 0.0 3.1415"/>
        <geom mesh="solo12_hip_fe_7" material="pla_white" class="visual" euler="0.0 0.0 3.1415"/>
        <geom mesh="solo12_hip_fe_8" material="metal_silver" class="visual" euler="0.0 0.0 3.1415"/>
        <geom mesh="solo12_hip_fe_10" material="metal_dark" class="visual" euler="0.0 0.0 3.1415"/>
        <geom mesh="solo12_hip_fe_11" material="metal_gold" class="visual" euler="0.0 0.0 3.1415"/>
        <geom mesh="solo12_hip_fe_12" material="metal_dark" class="visual" euler="0.0 0.0 3.1415"/>
        <geom mesh="solo12_hip_fe_13" material="metal_dark" class="visual" euler="0.0 0.0 3.1415"/>
        <geom mesh="solo12_hip_fe_14" material="metal_dark" class="visual" euler="0.0 0.0 3.1415"/> -->
        <!-- <geom mesh="solo12_hip_fe_collision_0" class="collision" euler="0.0 0.0 3.1415"/>
        <geom mesh="solo12_hip_fe_collision_1" class="collision" euler="0.0 0.0 3.1415"/>
        <geom mesh="solo12_hip_fe_collision_2" class="collision" euler="0.0 0.0 3.1415"/>
        <geom mesh="solo12_hip_fe_collision_3" class="collision" euler="0.0 0.0 3.1415"/>
        <geom mesh="solo12_hip_fe_collision_4" class="collision" euler="0.0 0.0 3.1415"/>
        <geom mesh="solo12_hip_fe_collision_5" class="collision" euler="0.0 0.0 3.1415"/> -->
      </body>
    </body>
  </worldbody>

  <actuator>
    <position class="affine" joint="FL_HAA" name="FL_HAA"/>
    <position class="affine" joint="FL_HFE" name="FL_HFE"/>
    <position class="affine" joint="FL_KFE" name="FL_KFE"/>
    <position class="affine" joint="FR_HAA" name="FR_HAA"/>
    <position class="affine" joint="FR_HFE" name="FR_HFE"/>
    <position class="affine" joint="FR_KFE" name="FR_KFE"/>
    <position class="affine" joint="HL_HAA" name="HL_HAA"/>
    <position class="affine" joint="HL_HFE" name="HL_HFE"/>
    <position class="affine" joint="HL_KFE" name="HL_KFE"/>
    <position class="affine" joint="HR_HAA" name="HR_HAA"/>
    <position class="affine" joint="HR_HFE" name="HR_HFE"/>
    <position class="affine" joint="HR_KFE" name="HR_KFE"/>
  </actuator>
  
  <!-- Collision exclusion from SRDF (robot_properties_solo) -->
  <contact>
    <!-- The base should not block shoulder rotation -->
    <exclude body1="FL_SHOULDER" body2="base_link"/>
    <exclude body1="FR_SHOULDER" body2="base_link"/>
    <exclude body1="HL_SHOULDER" body2="base_link"/>
    <exclude body1="HR_SHOULDER" body2="base_link"/>

    <!-- Exclude collisions of adjacent components -->
    <!-- Shoulders and upper legs -->
    <exclude body1="FL_UPPER_LEG" body2="FL_SHOULDER"/>
    <exclude body1="FR_UPPER_LEG" body2="FR_SHOULDER"/>
    <exclude body1="HL_UPPER_LEG" body2="HL_SHOULDER"/>
    <exclude body1="HR_UPPER_LEG" body2="HR_SHOULDER"/>

    <!-- Upper legs and lower legs -->
    <exclude body1="FL_LOWER_LEG" body2="FL_UPPER_LEG"/>
    <exclude body1="FR_LOWER_LEG" body2="FR_UPPER_LEG"/>
    <exclude body1="HL_LOWER_LEG" body2="HL_UPPER_LEG"/>
    <exclude body1="HR_LOWER_LEG" body2="HR_UPPER_LEG"/>
  </contact>

  <keyframe>
    <key name="home" qpos="0 0 0 1 0 0 0 0 0.0 0.0 0 0.0 0.0 0 0.0 0.0 0 0.0 0.0" />
  </keyframe>
</mujoco>